[2025-06-09T17:29:37.465+0200] {local_task_job_runner.py:120} INFO - ::group::Pre task execution logs
[2025-06-09T17:29:37.480+0200] {taskinstance.py:2073} INFO - Dependencies all met for dep_context=non-requeueable deps ti=<TaskInstance: backfill_pollution_weather_dag.format_backfill_all_data manual__2025-06-09T15:29:22.874038+00:00 [queued]>
[2025-06-09T17:29:37.483+0200] {taskinstance.py:2073} INFO - Dependencies all met for dep_context=requeueable deps ti=<TaskInstance: backfill_pollution_weather_dag.format_backfill_all_data manual__2025-06-09T15:29:22.874038+00:00 [queued]>
[2025-06-09T17:29:37.484+0200] {taskinstance.py:2303} INFO - Starting attempt 1 of 2
[2025-06-09T17:29:37.505+0200] {taskinstance.py:2327} INFO - Executing <Task(PythonOperator): format_backfill_all_data> on 2025-06-09 15:29:22.874038+00:00
[2025-06-09T17:29:37.507+0200] {standard_task_runner.py:63} INFO - Started process 106272 to run task
[2025-06-09T17:29:37.511+0200] {standard_task_runner.py:90} INFO - Running: ['airflow', 'tasks', 'run', 'backfill_pollution_weather_dag', 'format_backfill_all_data', 'manual__2025-06-09T15:29:22.874038+00:00', '--job-id', '395', '--raw', '--subdir', 'DAGS_FOLDER/backfill_dag.py', '--cfg-path', '/tmp/tmphmq3y8zc']
[2025-06-09T17:29:37.511+0200] {standard_task_runner.py:91} INFO - Job 395: Subtask format_backfill_all_data
[2025-06-09T17:29:37.551+0200] {task_command.py:426} INFO - Running <TaskInstance: backfill_pollution_weather_dag.format_backfill_all_data manual__2025-06-09T15:29:22.874038+00:00 [running]> on host DESKTOP-2QS8J6D.
[2025-06-09T17:29:37.622+0200] {taskinstance.py:2644} INFO - Exporting env vars: AIRFLOW_CTX_DAG_OWNER='airflow' AIRFLOW_CTX_DAG_ID='backfill_pollution_weather_dag' AIRFLOW_CTX_TASK_ID='format_backfill_all_data' AIRFLOW_CTX_EXECUTION_DATE='2025-06-09T15:29:22.874038+00:00' AIRFLOW_CTX_TRY_NUMBER='1' AIRFLOW_CTX_DAG_RUN_ID='manual__2025-06-09T15:29:22.874038+00:00'
[2025-06-09T17:29:37.623+0200] {taskinstance.py:430} INFO - ::endgroup::
[2025-06-09T17:29:44.603+0200] {logging_mixin.py:188} INFO - [CITY] Processing: istanbul
[2025-06-09T17:29:44.624+0200] {logging_mixin.py:188} WARNING - /home/ccd/airflow/dags/backfill_dag.py:136 SettingWithCopyWarning: 
A value is trying to be set on a copy of a slice from a DataFrame.
Try using .loc[row_indexer,col_indexer] = value instead

See the caveats in the documentation: https://pandas.pydata.org/pandas-docs/stable/user_guide/indexing.html#returning-a-view-versus-a-copy
[2025-06-09T17:29:44.625+0200] {logging_mixin.py:188} WARNING - /home/ccd/airflow/dags/backfill_dag.py:137 SettingWithCopyWarning: 
A value is trying to be set on a copy of a slice from a DataFrame.
Try using .loc[row_indexer,col_indexer] = value instead

See the caveats in the documentation: https://pandas.pydata.org/pandas-docs/stable/user_guide/indexing.html#returning-a-view-versus-a-copy
[2025-06-09T17:29:44.627+0200] {logging_mixin.py:188} WARNING - /home/ccd/airflow/dags/backfill_dag.py:138 SettingWithCopyWarning: 
A value is trying to be set on a copy of a slice from a DataFrame.
Try using .loc[row_indexer,col_indexer] = value instead

See the caveats in the documentation: https://pandas.pydata.org/pandas-docs/stable/user_guide/indexing.html#returning-a-view-versus-a-copy
[2025-06-09T17:29:44.633+0200] {taskinstance.py:441} INFO - ::group::Post task execution logs
[2025-06-09T17:29:44.634+0200] {taskinstance.py:2890} ERROR - Task failed with exception
Traceback (most recent call last):
  File "/home/ccd/airflow_venv/lib/python3.10/site-packages/airflow/models/taskinstance.py", line 465, in _execute_task
    result = _execute_callable(context=context, **execute_callable_kwargs)
  File "/home/ccd/airflow_venv/lib/python3.10/site-packages/airflow/models/taskinstance.py", line 432, in _execute_callable
    return execute_callable(context=context, **execute_callable_kwargs)
  File "/home/ccd/airflow_venv/lib/python3.10/site-packages/airflow/models/baseoperator.py", line 400, in wrapper
    return func(self, *args, **kwargs)
  File "/home/ccd/airflow_venv/lib/python3.10/site-packages/airflow/operators/python.py", line 235, in execute
    return_value = self.execute_callable()
  File "/home/ccd/airflow_venv/lib/python3.10/site-packages/airflow/operators/python.py", line 252, in execute_callable
    return self.python_callable(*self.op_args, **self.op_kwargs)
  File "/home/ccd/airflow/dags/backfill_dag.py", line 191, in format_backfill_all_dates
    df_agg = aggregate_pollution(df_day)
  File "/home/ccd/airflow/dags/backfill_dag.py", line 150, in aggregate_pollution
    'time': df_daytime['date'].iloc[2]
  File "/home/ccd/airflow_venv/lib/python3.10/site-packages/pandas/core/indexing.py", line 1191, in __getitem__
    return self._getitem_axis(maybe_callable, axis=axis)
  File "/home/ccd/airflow_venv/lib/python3.10/site-packages/pandas/core/indexing.py", line 1752, in _getitem_axis
    self._validate_integer(key, axis)
  File "/home/ccd/airflow_venv/lib/python3.10/site-packages/pandas/core/indexing.py", line 1685, in _validate_integer
    raise IndexError("single positional indexer is out-of-bounds")
IndexError: single positional indexer is out-of-bounds
[2025-06-09T17:29:44.640+0200] {taskinstance.py:1205} INFO - Marking task as UP_FOR_RETRY. dag_id=backfill_pollution_weather_dag, task_id=format_backfill_all_data, execution_date=20250609T152922, start_date=20250609T152937, end_date=20250609T152944
[2025-06-09T17:29:44.661+0200] {standard_task_runner.py:110} ERROR - Failed to execute job 395 for task format_backfill_all_data (single positional indexer is out-of-bounds; 106272)
[2025-06-09T17:29:44.672+0200] {local_task_job_runner.py:240} INFO - Task exited with return code 1
[2025-06-09T17:29:44.687+0200] {taskinstance.py:3482} INFO - 0 downstream tasks scheduled from follow-on schedule check
[2025-06-09T17:29:44.688+0200] {local_task_job_runner.py:222} INFO - ::endgroup::
