[2025-06-08T23:20:08.080+0200] {local_task_job_runner.py:120} INFO - ::group::Pre task execution logs
[2025-06-08T23:20:08.106+0200] {taskinstance.py:2073} INFO - Dependencies all met for dep_context=non-requeueable deps ti=<TaskInstance: backfill_pollution_weather_dag.format_pollution_backfill manual__2025-06-08T21:20:02.268249+00:00 [queued]>
[2025-06-08T23:20:08.113+0200] {taskinstance.py:2073} INFO - Dependencies all met for dep_context=requeueable deps ti=<TaskInstance: backfill_pollution_weather_dag.format_pollution_backfill manual__2025-06-08T21:20:02.268249+00:00 [queued]>
[2025-06-08T23:20:08.114+0200] {taskinstance.py:2303} INFO - Starting attempt 1 of 1
[2025-06-08T23:20:08.142+0200] {taskinstance.py:2327} INFO - Executing <Task(PythonOperator): format_pollution_backfill> on 2025-06-08 21:20:02.268249+00:00
[2025-06-08T23:20:08.147+0200] {standard_task_runner.py:63} INFO - Started process 1202549 to run task
[2025-06-08T23:20:08.154+0200] {standard_task_runner.py:90} INFO - Running: ['airflow', 'tasks', 'run', 'backfill_pollution_weather_dag', 'format_pollution_backfill', 'manual__2025-06-08T21:20:02.268249+00:00', '--job-id', '307', '--raw', '--subdir', 'DAGS_FOLDER/backfill_dag.py', '--cfg-path', '/tmp/tmpl3pc0u1t']
[2025-06-08T23:20:08.155+0200] {standard_task_runner.py:91} INFO - Job 307: Subtask format_pollution_backfill
[2025-06-08T23:20:08.221+0200] {task_command.py:426} INFO - Running <TaskInstance: backfill_pollution_weather_dag.format_pollution_backfill manual__2025-06-08T21:20:02.268249+00:00 [running]> on host DESKTOP-2QS8J6D.
[2025-06-08T23:20:08.349+0200] {taskinstance.py:2644} INFO - Exporting env vars: AIRFLOW_CTX_DAG_OWNER='airflow' AIRFLOW_CTX_DAG_ID='backfill_pollution_weather_dag' AIRFLOW_CTX_TASK_ID='format_pollution_backfill' AIRFLOW_CTX_EXECUTION_DATE='2025-06-08T21:20:02.268249+00:00' AIRFLOW_CTX_TRY_NUMBER='1' AIRFLOW_CTX_DAG_RUN_ID='manual__2025-06-08T21:20:02.268249+00:00'
[2025-06-08T23:20:08.351+0200] {taskinstance.py:430} INFO - ::endgroup::
[2025-06-08T23:20:19.961+0200] {taskinstance.py:441} INFO - ::group::Post task execution logs
[2025-06-08T23:20:19.962+0200] {taskinstance.py:2890} ERROR - Task failed with exception
Traceback (most recent call last):
  File "/home/ccd/airflow_venv/lib/python3.10/site-packages/pandas/core/indexes/base.py", line 3805, in get_loc
    return self._engine.get_loc(casted_key)
  File "index.pyx", line 167, in pandas._libs.index.IndexEngine.get_loc
  File "index.pyx", line 196, in pandas._libs.index.IndexEngine.get_loc
  File "pandas/_libs/hashtable_class_helper.pxi", line 7081, in pandas._libs.hashtable.PyObjectHashTable.get_item
  File "pandas/_libs/hashtable_class_helper.pxi", line 7089, in pandas._libs.hashtable.PyObjectHashTable.get_item
KeyError: 'time'

The above exception was the direct cause of the following exception:

Traceback (most recent call last):
  File "/home/ccd/airflow_venv/lib/python3.10/site-packages/airflow/models/taskinstance.py", line 465, in _execute_task
    result = _execute_callable(context=context, **execute_callable_kwargs)
  File "/home/ccd/airflow_venv/lib/python3.10/site-packages/airflow/models/taskinstance.py", line 432, in _execute_callable
    return execute_callable(context=context, **execute_callable_kwargs)
  File "/home/ccd/airflow_venv/lib/python3.10/site-packages/airflow/models/baseoperator.py", line 400, in wrapper
    return func(self, *args, **kwargs)
  File "/home/ccd/airflow_venv/lib/python3.10/site-packages/airflow/operators/python.py", line 235, in execute
    return_value = self.execute_callable()
  File "/home/ccd/airflow_venv/lib/python3.10/site-packages/airflow/operators/python.py", line 252, in execute_callable
    return self.python_callable(*self.op_args, **self.op_kwargs)
  File "/home/ccd/airflow/dags/backfill_dag.py", line 142, in format_pollution_backfill
    for date_str in df_flat['time'].unique():
  File "/home/ccd/airflow_venv/lib/python3.10/site-packages/pandas/core/frame.py", line 4102, in __getitem__
    indexer = self.columns.get_loc(key)
  File "/home/ccd/airflow_venv/lib/python3.10/site-packages/pandas/core/indexes/base.py", line 3812, in get_loc
    raise KeyError(key) from err
KeyError: 'time'
[2025-06-08T23:20:19.977+0200] {taskinstance.py:1205} INFO - Marking task as FAILED. dag_id=backfill_pollution_weather_dag, task_id=format_pollution_backfill, execution_date=20250608T212002, start_date=20250608T212008, end_date=20250608T212019
[2025-06-08T23:20:20.019+0200] {standard_task_runner.py:110} ERROR - Failed to execute job 307 for task format_pollution_backfill ('time'; 1202549)
[2025-06-08T23:20:20.049+0200] {local_task_job_runner.py:240} INFO - Task exited with return code 1
[2025-06-08T23:20:20.094+0200] {taskinstance.py:3482} INFO - 0 downstream tasks scheduled from follow-on schedule check
[2025-06-08T23:20:20.121+0200] {local_task_job_runner.py:222} INFO - ::endgroup::
